 * Serving Flask app "app" (lazy loading)
 * Environment: production
   WARNING: This is a development server. Do not use it in a production deployment.
   Use a production WSGI server instead.
 * Debug mode: on
 * Running on http://0.0.0.0:5000/ (Press CTRL+C to quit)
 * Restarting with stat
 * Debugger is active!
 * Debugger PIN: 228-560-516
10.0.2.2 - - [11/Mar/2021 19:36:59] "[35m[1mGET /balance/hidey HTTP/1.1[0m" 500 -
Traceback (most recent call last):
  File "/usr/local/lib/python3.8/dist-packages/flask/app.py", line 2464, in __call__
    return self.wsgi_app(environ, start_response)
  File "/usr/local/lib/python3.8/dist-packages/flask/app.py", line 2450, in wsgi_app
    response = self.handle_exception(e)
  File "/usr/local/lib/python3.8/dist-packages/flask_restful/__init__.py", line 272, in error_router
    return original_handler(e)
  File "/usr/local/lib/python3.8/dist-packages/flask/app.py", line 1867, in handle_exception
    reraise(exc_type, exc_value, tb)
  File "/usr/local/lib/python3.8/dist-packages/flask/_compat.py", line 38, in reraise
    raise value.with_traceback(tb)
  File "/usr/local/lib/python3.8/dist-packages/flask/app.py", line 2447, in wsgi_app
    response = self.full_dispatch_request()
  File "/usr/local/lib/python3.8/dist-packages/flask/app.py", line 1952, in full_dispatch_request
    rv = self.handle_user_exception(e)
  File "/usr/local/lib/python3.8/dist-packages/flask_restful/__init__.py", line 272, in error_router
    return original_handler(e)
  File "/usr/local/lib/python3.8/dist-packages/flask/app.py", line 1821, in handle_user_exception
    reraise(exc_type, exc_value, tb)
  File "/usr/local/lib/python3.8/dist-packages/flask/_compat.py", line 38, in reraise
    raise value.with_traceback(tb)
  File "/usr/local/lib/python3.8/dist-packages/flask/app.py", line 1950, in full_dispatch_request
    rv = self.dispatch_request()
  File "/usr/local/lib/python3.8/dist-packages/flask/app.py", line 1936, in dispatch_request
    return self.view_functions[rule.endpoint](**req.view_args)
  File "/usr/local/lib/python3.8/dist-packages/flask_restful/__init__.py", line 468, in wrapper
    resp = resource(*args, **kwargs)
  File "/usr/local/lib/python3.8/dist-packages/flask/views.py", line 89, in view
    return self.dispatch_request(*args, **kwargs)
  File "/usr/local/lib/python3.8/dist-packages/flask_restful/__init__.py", line 583, in dispatch_request
    resp = meth(*args, **kwargs)
  File "/opt/flaskapp/app.py", line 71, in get
    if not db.check_user_exists(username):
  File "/opt/flaskapp/db/db.py", line 34, in check_user_exists
    cur.execute("SELECT firstName from users WHERE username=%s", [username])
psycopg2.errors.UndefinedTable: relation "users" does not exist
LINE 1: SELECT firstName from users WHERE username='hidey'
                              ^
10.0.2.2 - - [11/Mar/2021 19:37:38] "[35m[1mGET /balance/hidey HTTP/1.1[0m" 500 -
Traceback (most recent call last):
  File "/usr/local/lib/python3.8/dist-packages/flask/app.py", line 2464, in __call__
    return self.wsgi_app(environ, start_response)
  File "/usr/local/lib/python3.8/dist-packages/flask/app.py", line 2450, in wsgi_app
    response = self.handle_exception(e)
  File "/usr/local/lib/python3.8/dist-packages/flask_restful/__init__.py", line 272, in error_router
    return original_handler(e)
  File "/usr/local/lib/python3.8/dist-packages/flask/app.py", line 1867, in handle_exception
    reraise(exc_type, exc_value, tb)
  File "/usr/local/lib/python3.8/dist-packages/flask/_compat.py", line 38, in reraise
    raise value.with_traceback(tb)
  File "/usr/local/lib/python3.8/dist-packages/flask/app.py", line 2447, in wsgi_app
    response = self.full_dispatch_request()
  File "/usr/local/lib/python3.8/dist-packages/flask/app.py", line 1952, in full_dispatch_request
    rv = self.handle_user_exception(e)
  File "/usr/local/lib/python3.8/dist-packages/flask_restful/__init__.py", line 272, in error_router
    return original_handler(e)
  File "/usr/local/lib/python3.8/dist-packages/flask/app.py", line 1821, in handle_user_exception
    reraise(exc_type, exc_value, tb)
  File "/usr/local/lib/python3.8/dist-packages/flask/_compat.py", line 38, in reraise
    raise value.with_traceback(tb)
  File "/usr/local/lib/python3.8/dist-packages/flask/app.py", line 1950, in full_dispatch_request
    rv = self.dispatch_request()
  File "/usr/local/lib/python3.8/dist-packages/flask/app.py", line 1936, in dispatch_request
    return self.view_functions[rule.endpoint](**req.view_args)
  File "/usr/local/lib/python3.8/dist-packages/flask_restful/__init__.py", line 468, in wrapper
    resp = resource(*args, **kwargs)
  File "/usr/local/lib/python3.8/dist-packages/flask/views.py", line 89, in view
    return self.dispatch_request(*args, **kwargs)
  File "/usr/local/lib/python3.8/dist-packages/flask_restful/__init__.py", line 583, in dispatch_request
    resp = meth(*args, **kwargs)
  File "/opt/flaskapp/app.py", line 71, in get
    if not db.check_user_exists(username):
  File "/opt/flaskapp/db/db.py", line 34, in check_user_exists
    cur.execute("SELECT firstName from users WHERE username=%s", [username])
psycopg2.errors.UndefinedTable: relation "users" does not exist
LINE 1: SELECT firstName from users WHERE username='hidey'
                              ^
10.0.2.2 - - [12/Mar/2021 06:09:02] "[35m[1mPOST /user/youzhini HTTP/1.1[0m" 500 -
Traceback (most recent call last):
  File "/usr/local/lib/python3.8/dist-packages/flask/app.py", line 2464, in __call__
    return self.wsgi_app(environ, start_response)
  File "/usr/local/lib/python3.8/dist-packages/flask/app.py", line 2450, in wsgi_app
    response = self.handle_exception(e)
  File "/usr/local/lib/python3.8/dist-packages/flask_restful/__init__.py", line 272, in error_router
    return original_handler(e)
  File "/usr/local/lib/python3.8/dist-packages/flask/app.py", line 1867, in handle_exception
    reraise(exc_type, exc_value, tb)
  File "/usr/local/lib/python3.8/dist-packages/flask/_compat.py", line 38, in reraise
    raise value.with_traceback(tb)
  File "/usr/local/lib/python3.8/dist-packages/flask/app.py", line 2447, in wsgi_app
    response = self.full_dispatch_request()
  File "/usr/local/lib/python3.8/dist-packages/flask/app.py", line 1952, in full_dispatch_request
    rv = self.handle_user_exception(e)
  File "/usr/local/lib/python3.8/dist-packages/flask_restful/__init__.py", line 272, in error_router
    return original_handler(e)
  File "/usr/local/lib/python3.8/dist-packages/flask/app.py", line 1821, in handle_user_exception
    reraise(exc_type, exc_value, tb)
  File "/usr/local/lib/python3.8/dist-packages/flask/_compat.py", line 38, in reraise
    raise value.with_traceback(tb)
  File "/usr/local/lib/python3.8/dist-packages/flask/app.py", line 1950, in full_dispatch_request
    rv = self.dispatch_request()
  File "/usr/local/lib/python3.8/dist-packages/flask/app.py", line 1936, in dispatch_request
    return self.view_functions[rule.endpoint](**req.view_args)
  File "/usr/local/lib/python3.8/dist-packages/flask_restful/__init__.py", line 468, in wrapper
    resp = resource(*args, **kwargs)
  File "/usr/local/lib/python3.8/dist-packages/flask/views.py", line 89, in view
    return self.dispatch_request(*args, **kwargs)
  File "/usr/local/lib/python3.8/dist-packages/flask_restful/__init__.py", line 583, in dispatch_request
    resp = meth(*args, **kwargs)
  File "/opt/flaskapp/app.py", line 50, in post
    if db.check_user_exists(username):
  File "/opt/flaskapp/db/db.py", line 34, in check_user_exists
    cur.execute("SELECT firstName from users WHERE username=%s", [username])
psycopg2.errors.UndefinedTable: relation "users" does not exist
LINE 1: SELECT firstName from users WHERE username='youzhini'
                              ^
10.0.2.2 - - [12/Mar/2021 06:44:56] "[37mGET /user/hidey HTTP/1.1[0m" 200 -
10.0.2.2 - - [12/Mar/2021 06:45:42] "[37mPOST /user/cheekeenwong HTTP/1.1[0m" 200 -
10.0.2.2 - - [12/Mar/2021 06:46:10] "[37mPOST /user/janet HTTP/1.1[0m" 200 -
10.0.2.2 - - [12/Mar/2021 06:46:29] "[37mPOST /transfer/cheekeenwong HTTP/1.1[0m" 200 -
10.0.2.2 - - [12/Mar/2021 06:46:46] "[37mPOST /balance/cheekeenwong HTTP/1.1[0m" 200 -
10.0.2.2 - - [12/Mar/2021 06:46:54] "[37mPOST /transfer/cheekeenwong HTTP/1.1[0m" 200 -
10.0.2.2 - - [12/Mar/2021 06:48:28] "[37mGET / HTTP/1.1[0m" 200 -
10.0.2.2 - - [12/Mar/2021 06:50:29] "[37mGET / HTTP/1.1[0m" 200 -
10.0.2.2 - - [12/Mar/2021 06:50:30] "[33mGET /static/style.css HTTP/1.1[0m" 404 -
10.0.2.2 - - [12/Mar/2021 06:50:31] "[33mGET /favicon.ico HTTP/1.1[0m" 404 -
10.0.2.2 - - [12/Mar/2021 06:52:07] "[37mPOST //transfer/cheekeenwong HTTP/1.1[0m" 200 -
10.0.2.2 - - [12/Mar/2021 06:52:49] "[37mPOST //user/hardeep HTTP/1.1[0m" 200 -
